Workbook

Sheet Content
B2: Sheet name | C2: Content | D2: Relevant propulsion technologies
B3: Result matrix | C3: Matrices for results of VECTO in the MRF and CIF according to the individual propulsion technologies. "Weighted" results are only relevant for the CIF | D3: all
B4: GenericData_VehicleOperation | C4: Tables with generic data | D4: all xEV (HEV, PEV, FCHV)
B5: Usable_SOC | C5: Calculation of the usable SOC range for the different xEV concepts | D5: all OVC-xEV (HEV, PEV, FCHV)
B6: BatteryData OVC-HEV | C6: Calculation of battery charging efficiency for external ("OVC") charging event(s) | D6: OVC HEV and OVC FCHV
B7: Template_OVC-HEV | C7: Calculation example for all post-processing elements regarding fuel consumption, electrical energy consumption as well as CO2 emissions
B8: BatteryData PEV | C8: Calculation of battery charging efficiency for external ("OVC") charging event(s) | D8: PEV
B9: Template_PEV | C9: Calculation example for all post-processing elements regarding fuel consumption, electrical energy consumption as well as CO2 emissions
B10: BatteryData IMC_OVC-HEV | C10: Calculation of battery charging efficiency for external ("OVC") charging event(s) | D10: OVC HEV and OVC FCHV with additional IMC feature
B11: Template IMC_OVC-HEV | C11: Calculation example for all post-processing elements regarding fuel consumption, electrical energy consumption as well as CO2 emissions
B12: BatteryData IMC_PEV | C12: Calculation of battery charging efficiency for external ("OVC") charging event(s) | D12: PEV with additional IMC feature
B13: Template IMC_PEV | C13: Calculation example for all post-processing elements regarding fuel consumption, electrical energy consumption as well as CO2 emissions

Sheet Result matrix
C2: X | D2: individual result simulated in specific mode (i.e. CS or CD)
C3: (X) | D3: result from specific mode (i.e. CS or CD) without direct output but relevant for total results
C4: X | D4: post-processing result from above (i.e. grey X) given as output in total results element
C5: X | D5: weighted result produced by weighted averaging from CS and CD
B8: Pure ICE vehicles, non-OVC HEVs and non-OVC FCHVs
B9: Mission profile | C9: Payload | D9: Result level | E9: v_average | F9: Fuel consumption per fuel type | G9: CO2 emissions | H9: Electric energy consumption | I9: Actual charge depleting range RCDA | J9: Equivalent all electric range (EAER) | K9: Hydrogen range (H2R) | L9: Zero CO2 emissions range | N9: Electric range for UF | O9: UF | Q9: FC_ZEV_AuxHeater | R9: CO2_ZEV_AuxHeater
E10: [km/h] | F10: [lit/100km] ... | G10: [g/km] ... | H10: [kWh/km] ... | I10: [km] | J10: [km] | K10: [km] | L10: [km] | N10: [km] | O10: [-] | Q10: [lit/100km] ... | R10: [g/km] ...
B11: #1 | C11: low | D11: OVC mode CD | E11: --- | F11: --- | G11: --- | H11: --- | I11: --- | J11: --- | K11: --- | L11: --- | N11: --- | O11: --- | Q11: --- | R11: ---
B12: #1 | C12: low | D12: OVC mode CS | E12: (X) | F12: (X) | G12: (X) | H12: --- | I12: --- | J12: --- | K12: (X)1 | L12: (X)1 | N12: --- | O12: --- | Q12: (X)1 | R12: (X)1
B13: #1 | C13: low | D13: Total | E13: X | F13: X | G13: X | H13: --- | I13: --- | J13: --- | K13: X1 | L13: X1 | N13: --- | O13: --- | Q13: X1 | R13: X1
B14: #1 | C14: rep. | D14: OVC mode CD | E14: --- | F14: --- | G14: --- | H14: --- | I14: --- | J14: --- | K14: --- | L14: --- | N14: --- | O14: --- | Q14: --- | R14: ---
B15: #1 | C15: rep. | D15: OVC mode CS | E15: (X) | F15: (X) | G15: (X) | H15: --- | I15: --- | J15: --- | K15: (X)1 | L15: (X)1 | N15: --- | O15: --- | Q15: (X)1 | R15: (X)1
B16: #1 | C16: rep. | D16: Total | E16: X | F16: X | G16: X | H16: --- | I16: --- | J16: --- | K16: X1 | L16: X1 | N16: --- | O16: --- | Q16: X1 | R16: X1
B17: #2 | C17: low | D17: OVC mode CD | E17: --- | F17: --- | G17: --- | H17: --- | I17: --- | J17: --- | K17: --- | L17: --- | N17: --- | O17: --- | Q17: --- | R17: ---
B18: #2 | C18: low | D18: OVC mode CS | E18: (X) | F18: (X) | G18: (X) | H18: --- | I18: --- | J18: --- | K18: (X)1 | L18: (X)1 | N18: --- | O18: --- | Q18: (X)1 | R18: (X)1
B19: #2 | C19: low | D19: Total | E19: X | F19: X | G19: X | H19: --- | I19: --- | J19: --- | K19: X1 | L19: X1 | N19: --- | O19: --- | Q19: X1 | R19: X1
B20: #2 | C20: rep. | D20: OVC mode CD | E20: --- | F20: --- | G20: --- | H20: --- | I20: --- | J20: --- | K20: --- | L20: --- | N20: --- | O20: --- | Q20: --- | R20: ---
B21: #2 | C21: rep. | D21: OVC mode CS | E21: (X) | F21: (X) | G21: (X) | H21: --- | I21: --- | J21: --- | K21: (X)1 | L21: (X)1 | N21: --- | O21: --- | Q21: (X)1 | R21: (X)1
B22: #2 | C22: rep. | D22: Total | E22: X | F22: X | G22: X | H22: --- | I22: --- | J22: --- | K22: X1 | L22: X1 | N22: --- | O22: --- | Q22: X1 | R22: X1
B23: #3 | C23: ... | D23: ... | E23: ... | F23: ... | G23: ... | H23: --- | I23: --- | J23: --- | K23: ... | L23: ... | N23: --- | O23: --- | Q23: ... | R23: ...
B24: weighted | E24: --- | F24: X | G24: X | H24: --- | I24: --- | J24: --- | K24: X1 | L24: X1 | N24: --- | O24: --- | Q24: X1 | R24: X1
B25: 1 ... Only for H2 propulsion vehicles (ICE and FCHV)
B26: 2 ... Not for H2 propulsion vehicles (ICE and FCHV)
B28: OVC HEV and OVC-FCHV
B29: Mission profile | C29: Payload | D29: Result level | E29: v_average | F29: Fuel consumption per fuel type | G29: CO2 emissions | H29: Electric energy consumption | I29: Actual charge depleting range RCDA | J29: Equivalent all electric range (EAER) | K29: Hydrogen range (H2R) | L29: Zero CO2 emissions range | N29: Electric range for UF | O29: UF | Q29: FC_ZEV_AuxHeater | R29: CO2_ZEV_AuxHeater
E30: [km/h] | F30: [lit/100km] ... | G30: [g/km] ... | H30: [kWh/km] ... | I30: [km] | J30: [km] | K30: [km] | L30: [km] | N30: [km] | O30: [-] | Q30: [lit/100km] ... | R30: [g/km] ...
B31: #1 | C31: low | D31: OVC mode CD | E31: X | F31: X | G31: X | H31: X | I31: (X) | J31: (X) | K31: --- | L31: --- | N31: --- | O31: --- | Q31: X1 | R31: X1
B32: #1 | C32: low | D32: OVC mode CS | E32: X | F32: X | G32: X | H32: --- | I32: --- | J32: --- | K32: (X)1 | L32: --- | N32: --- | O32: --- | Q32: X1 | R32: X1
B33: #1 | C33: low | D33: Total | E33: X2 | F33: X2 | G33: X2 | H33: X2 | I33: X | J33: X | K33: X1 | L33: X | N33: X2 | O33: X2 | Q33: X2 | R33: X2
B34: #1 | C34: rep. | D34: OVC mode CD | E34: X | F34: X | G34: X | H34: X | I34: (X) | J34: (X) | K34: --- | L34: --- | N34: --- | O34: --- | Q34: X1 | R34: X1
B35: #1 | C35: rep. | D35: OVC mode CS | E35: X | F35: X | G35: X | H35: --- | I35: --- | J35: --- | K35: (X)1 | L35: --- | N35: --- | O35: --- | Q35: X1 | R35: X1
B36: #1 | C36: rep. | D36: Total | E36: X2 | F36: X2 | G36: X2 | H36: X2 | I36: X | J36: X | K36: X1 | L36: X | N36: X2 | O36: X2 | Q36: X2 | R36: X2
B37: #2 | C37: low | D37: OVC mode CD | E37: X | F37: X | G37: X | H37: X | I37: (X) | J37: (X) | K37: --- | L37: --- | N37: --- | O37: --- | Q37: X1 | R37: X1
B38: #2 | C38: low | D38: OVC mode CS | E38: X | F38: X | G38: X | H38: --- | I38: --- | J38: --- | K38: (X)1 | L38: --- | N38: --- | O38: --- | Q38: X1 | R38: X1
B39: #2 | C39: low | D39: Total | E39: X2 | F39: X2 | G39: X2 | H39: X2 | I39: X | J39: X | K39: X1 | L39: X | N39: X2 | O39: X2 | Q39: X2 | R39: X2
B40: #2 | C40: rep. | D40: OVC mode CD | E40: X | F40: X | G40: X | H40: X | I40: (X) | J40: (X) | K40: --- | L40: --- | N40: --- | O40: --- | Q40: X1 | R40: X1
B41: #2 | C41: rep. | D41: OVC mode CS | E41: X | F41: X | G41: X | H41: --- | I41: --- | J41: --- | K41: (X)1 | L41: --- | N41: --- | O41: --- | Q41: X1 | R41: X1
B42: #2 | C42: rep. | D42: Total | E42: X2 | F42: X2 | G42: X2 | H42: X2 | I42: X | J42: X | K42: X1 | L42: X | N42: X2 | O42: X2 | Q42: X2 | R42: X2
B43: #3 | C43: ... | D43: ... | E43: ... | F43: ... | G43: ... | H43: ... | I43: ... | J43: ... | K43: ... | N43: ... | O43: ... | Q43: ... | R43: ...
B44: weighted | E44: --- | F44: X2 | G44: X2 | H44: X2 | I44: X | J44: X | K44: X1 | L44: X | N44: --- | O44: --- | Q44: --- | R44: ---
...

Sheet GenericData_VehicleOperation
B2: Vehicle group | D2: Annual mileage [km/a] | N2: Working days p.a. | O2: Daily mission specific mileage [km/d] | Z2: Vehicle group | AA2: Stationary charging during mission [kWh] | AL2: Vehicle group | AM2: Share of distance of total mission where in-motion charging infrastructure is available OVERHEAD CATENARY | AX2: Real world usage factors
D3: Long haul | E3: Regional delivery | F3: Urban delivery | G3: Municipal delivery | H3: Construction | I3: Heavy Urban | J3: Urban | K3: Suburban | L3: Interurban | M3: Coach | O3: Long haul | P3: Regional delivery | Q3: Urban delivery | R3: Municipal delivery | S3: Con-struction | T3: Heavy Urban | U3: Urban | V3: Suburban | W3: Interurban | X3: Coach | AA3: Long haul | AB3: Regional delivery | AC3: Urban delivery | AD3: Municipal delivery | AE3: Con-struction | AF3: Heavy Urban | AG3: Urban | AH3: Suburban | AI3: Interurban | AJ3: Coach | AM3: Long haul | AN3: Regional delivery | AO3: Urban delivery | AP3: Municipal delivery | AQ3: Con-struction | AR3: Heavy Urban | AS3: Urban | AT3: Suburban | AU3: Interurban | AV3: Coach | AX3: Start SOC before mission (depot) RF_StartSOC | AY3: Stationary charging during mission RF_StatCharge | AZ3: Real world factor in-motion charging during mission (lift in % of useable SOC) RF_IM_SOCLift
B4: 53 | D4: --- | E4: 80000 | F4: 60000 | G4: --- | H4: --- | I4: --- | J4: --- | K4: --- | L4: --- | M4: --- | N4: 250 | O4: --- | P4: =E4/$N4 -> 320 | Q4: =F4/$N4 -> 240 | R4: --- | S4: --- | T4: --- | U4: --- | V4: --- | W4: --- | X4: --- | Z4: 53 | AA4: --- | AB4: =AB31*AB58*AB85*$AY4 -> 125 | AC4: =AC31*AC58*AC85*$AY4 -> 250 | AD4: --- | AE4: --- | AF4: --- | AG4: --- | AH4: --- | AI4: --- | AJ4: --- | AL4: 53 | AM4: --- | AN4: 0 | AO4: 0 | AP4: --- | AQ4: --- | AR4: --- | AS4: --- | AT4: --- | AU4: --- | AV4: --- | AX4: 0.75 | AY4: 0.5 | AZ4: 0.5
B5: 54 | D5: --- | E5: 80000 | F5: 60000 | G5: --- | H5: --- | I5: --- | J5: --- | K5: --- | L5: --- | M5: --- | N5: 250 | O5: --- | P5: =E5/$N5 -> 320 | Q5: =F5/$N5 -> 240 | R5: --- | S5: --- | T5: --- | U5: --- | V5: --- | W5: --- | X5: --- | Z5: 54 | AA5: --- | AB5: =AB32*AB59*AB86*$AY5 -> 125 | AC5: =AC32*AC59*AC86*$AY5 -> 250 | AD5: --- | AE5: --- | AF5: --- | AG5: --- | AH5: --- | AI5: --- | AJ5: --- | AL5: 54 | AM5: --- | AN5: 0 | AO5: 0 | AP5: --- | AQ5: --- | AR5: --- | AS5: --- | AT5: --- | AU5: --- | AV5: --- | AX5: 0.75 | AY5: 0.5 | AZ5: 0.5
B6: 1s | D6: --- | E6: 80000 | F6: 60000 | G6: --- | H6: --- | I6: --- | J6: --- | K6: --- | L6: --- | M6: --- | N6: 250 | O6: --- | P6: =E6/$N6 -> 320 | Q6: =F6/$N6 -> 240 | R6: --- | S6: --- | T6: --- | U6: --- | V6: --- | W6: --- | X6: --- | Z6: 1s | AA6: --- | AB6: =AB33*AB60*AB87*$AY6 -> 125 | AC6: =AC33*AC60*AC87*$AY6 -> 250 | AD6: --- | AE6: --- | AF6: --- | AG6: --- | AH6: --- | AI6: --- | AJ6: --- | AL6: 1s | AM6: --- | AN6: =0.67/2 -> 0.335 | AO6: 0 | AP6: --- | AQ6: --- | AR6: --- | AS6: --- | AT6: --- | AU6: --- | AV6: --- | AX6: 0.75 | AY6: 0.5 | AZ6: 0.5
B7: 1 | D7: --- | E7: 80000 | F7: 60000 | G7: --- | H7: --- | I7: --- | J7: --- | K7: --- | L7: --- | M7: --- | N7: 250 | O7: --- | P7: =E7/$N7 -> 320 | Q7: =F7/$N7 -> 240 | R7: --- | S7: --- | T7: --- | U7: --- | V7: --- | W7: --- | X7: --- | Z7: 1 | AA7: --- | AB7: =AB34*AB61*AB88*$AY7 -> 125 | AC7: =AC34*AC61*AC88*$AY7 -> 250 | AD7: --- | AE7: --- | AF7: --- | AG7: --- | AH7: --- | AI7: --- | AJ7: --- | AL7: 1 | AM7: --- | AN7: =0.67/2 -> 0.335 | AO7: 0 | AP7: --- | AQ7: --- | AR7: --- | AS7: --- | AT7: --- | AU7: --- | AV7: --- | AX7: 0.75 | AY7: 0.5 | AZ7: 0.5
B8: 2 | D8: 120000 | E8: 80000 | F8: 60000 | G8: --- | H8: --- | I8: --- | J8: --- | K8: --- | L8: --- | M8: --- | N8: 250 | O8: =D8/$N8 -> 480 | P8: =E8/$N8 -> 320 | Q8: =F8/$N8 -> 240 | R8: --- | S8: --- | T8: --- | U8: --- | V8: --- | W8: --- | X8: --- | Z8: 2 | AA8: =AA35*AA62*AA89*$AY8 -> 125 | AB8: =AB35*AB62*AB89*$AY8 -> 125 | AC8: =AC35*AC62*AC89*$AY8 -> 250 | AD8: --- | AE8: --- | AF8: --- | AG8: --- | AH8: --- | AI8: --- | AJ8: --- | AL8: 2 | AM8: =0.5*1 -> 0.5 | AN8: =0.67/2 -> 0.335 | AO8: 0 | AP8: --- | AQ8: --- | AR8: --- | AS8: --- | AT8: --- | AU8: --- | AV8: --- | AX8: 0.75 | AY8: 0.5 | AZ8: 0.5
B9: 3 | D9: --- | E9: 80000 | F9: 60000 | G9: --- | H9: --- | I9: --- | J9: --- | K9: --- | L9: --- | M9: --- | N9: 250 | O9: --- | P9: =E9/$N9 -> 320 | Q9: =F9/$N9 -> 240 | R9: --- | S9: --- | T9: --- | U9: --- | V9: --- | W9: --- | X9: --- | Z9: 3 | AA9: --- | AB9: =AB36*AB63*AB90*$AY9 -> 125 | AC9: =AC36*AC63*AC90*$AY9 -> 250 | AD9: --- | AE9: --- | AF9: --- | AG9: --- | AH9: --- | AI9: --- | AJ9: --- | AL9: 3 | AM9: --- | AN9: =0.67/2 -> 0.335 | AO9: 0 | AP9: --- | AQ9: --- | AR9: --- | AS9: --- | AT9: --- | AU9: --- | AV9: --- | AX9: 0.75 | AY9: 0.5 | AZ9: 0.5
B10: 4 | D10: 120000 | E10: 80000 | F10: 60000 | G10: 25000 | H10: 60000 | I10: --- | J10: --- | K10: --- | L10: --- | M10: --- | N10: 250 | O10: =D10/$N10 -> 480 | P10: =E10/$N10 -> 320 | Q10: =F10/$N10 -> 240 | R10: =G10/$N10 -> 100 | S10: =H10/$N10 -> 240 | T10: --- | U10: --- | V10: --- | W10: --- | X10: --- | Z10: 4 | AA10: =AA37*AA64*AA91*$AY10 -> 125 | AB10: =AB37*AB64*AB91*$AY10 -> 125 | AC10: =AC37*AC64*AC91*$AY10 -> 250 | AD10: =AD37*AD64*AD91*$AY10 -> 150 | AE10: =AE37*AE64*AE91*$AY10 -> 50 | AF10: --- | AG10: --- | AH10: --- | AI10: --- | AJ10: --- | AL10: 4 | AM10: =0.5*1 -> 0.5 | AN10: =0.67/2 -> 0.335 | AO10: 0 | AP10: 0 | AQ10: 0 | AR10: --- | AS10: --- | AT10: --- | AU10: --- | AV10: --- | AX10: 0.75 | AY10: 0.5 | AZ10: 0.5
B11: 5 | D11: 120000 | E11: 80000 | F11: 60000 | G11: --- | H11: 60000 | I11: --- | J11: --- | K11: --- | L11: --- | M11: --- | N11: 250 | O11: =D11/$N11 -> 480 | P11: =E11/$N11 -> 320 | Q11: =F11/$N11 -> 240 | R11: --- | S11: =H11/$N11 -> 240 | T11: --- | U11: --- | V11: --- | W11: --- | X11: --- | Z11: 5 | AA11: =AA38*AA65*AA92*$AY11 -> 125 | AB11: =AB38*AB65*AB92*$AY11 -> 125 | AC11: =AC38*AC65*AC92*$AY11 -> 250 | AD11: --- | AE11: =AE38*AE65*AE92*$AY11 -> 50 | AF11: --- | AG11: --- | AH11: --- | AI11: --- | AJ11: --- | AL11: 5 | AM11: =0.5*1 -> 0.5 | AN11: =0.67/2 -> 0.335 | AO11: 0 | AP11: --- | AQ11: 0 | AR11: --- | AS11: --- | AT11: --- | AU11: --- | AV11: --- | AX11: 0.75 | AY11: 0.5 | AZ11: 0.5
B12: 9 | D12: 120000 | E12: 80000 | F12: --- | G12: 25000 | H12: 60000 | I12: --- | J12: --- | K12: --- | L12: --- | M12: --- | N12: 250 | O12: =D12/$N12 -> 480 | P12: =E12/$N12 -> 320 | Q12: --- | R12: =G12/$N12 -> 100 | S12: =H12/$N12 -> 240 | T12: --- | U12: --- | V12: --- | W12: --- | X12: --- | Z12: 9 | AA12: =AA39*AA66*AA93*$AY12 -> 125 | AB12: =AB39*AB66*AB93*$AY12 -> 125 | AC12: --- | AD12: =AD39*AD66*AD93*$AY12 -> 150 | AE12: =AE39*AE66*AE93*$AY12 -> 50 | AF12: --- | AG12: --- | AH12: --- | AI12: --- | AJ12: --- | AL12: 9 | AM12: =0.5*1 -> 0.5 | AN12: =0.67/2 -> 0.335 | AO12: --- | AP12: 0 | AQ12: 0 | AR12: --- | AS12: --- | AT12: --- | AU12: --- | AV12: --- | AX12: 0.75 | AY12: 0.5 | AZ12: 0.5
B13: 10 | D13: 120000 | E13: 80000 | F13: --- | G13: --- | H13: 60000 | I13: --- | J13: --- | K13: --- | L13: --- | M13: --- | N13: 250 | O13: =D13/$N13 -> 480 | P13: =E13/$N13 -> 320 | Q13: --- | R13: --- | S13: =H13/$N13 -> 240 | T13: --- | U13: --- | V13: --- | W13: --- | X13: --- | Z13: 10 | AA13: =AA40*AA67*AA94*$AY13 -> 125 | AB13: =AB40*AB67*AB94*$AY13 -> 125 | AC13: --- | AD13: --- | AE13: =AE40*AE67*AE94*$AY13 -> 50 | AF13: --- | AG13: --- | AH13: --- | AI13: --- | AJ13: --- | AL13: 10 | AM13: =0.5*1 -> 0.5 | AN13: =0.67/2 -> 0.335 | AO13: --- | AP13: --- | AQ13: 0 | AR13: --- | AS13: --- | AT13: --- | AU13: --- | AV13: --- | AX13: 0.75 | AY13: 0.5 | AZ13: 0.5
B14: 11 | D14: 120000 | E14: 80000 | F14: --- | G14: 25000 | H14: 60000 | I14: --- | J14: --- | K14: --- | L14: --- | M14: --- | N14: 250 | O14: =D14/$N14 -> 480 | P14: =E14/$N14 -> 320 | Q14: --- | R14: =G14/$N14 -> 100 | S14: =H14/$N14 -> 240 | T14: --- | U14: --- | V14: --- | W14: --- | X14: --- | Z14: 11 | AA14: =AA41*AA68*AA95*$AY14 -> 125 | AB14: =AB41*AB68*AB95*$AY14 -> 125 | AC14: --- | AD14: =AD41*AD68*AD95*$AY14 -> 150 | AE14: =AE41*AE68*AE95*$AY14 -> 50 | AF14: --- | AG14: --- | AH14: --- | AI14: --- | AJ14: --- | AL14: 11 | AM14: =0.5*1 -> 0.5 | AN14: =0.67/2 -> 0.335 | AO14: --- | AP14: 0 | AQ14: 0 | AR14: --- | AS14: --- | AT14: --- | AU14: --- | AV14: --- | AX14: 0.75 | AY14: 0.5 | AZ14: 0.5
B15: 12 | D15: 120000 | E15: 80000 | F15: --- | G15: --- | H15: 60000 | I15: --- | J15: --- | K15: --- | L15: --- | M15: --- | N15: 250 | O15: =D15/$N15 -> 480 | P15: =E15/$N15 -> 320 | Q15: --- | R15: --- | S15: =H15/$N15 -> 240 | T15: --- | U15: --- | V15: --- | W15: --- | X15: --- | Z15: 12 | AA15: =AA42*AA69*AA96*$AY15 -> 125 | AB15: =AB42*AB69*AB96*$AY15 -> 125 | AC15: --- | AD15: --- | AE15: =AE42*AE69*AE96*$AY15 -> 50 | AF15: --- | AG15: --- | AH15: --- | AI15: --- | AJ15: --- | AL15: 12 | AM15: =0.5*1 -> 0.5 | AN15: =0.67/2 -> 0.335 | AO15: --- | AP15: --- | AQ15: 0 | AR15: --- | AS15: --- | AT15: --- | AU15: --- | AV15: --- | AX15: 0.75 | AY15: 0.5 | AZ15: 0.5
B16: 16 | D16: --- | E16: --- | F16: --- | G16: --- | H16: 60000 | I16: --- | J16: --- | K16: --- | L16: --- | M16: --- | N16: 250 | O16: --- | P16: --- | Q16: --- | R16: --- | S16: =H16/$N16 -> 240 | T16: --- | U16: --- | V16: --- | W16: --- | X16: --- | Z16: 16 | AA16: --- | AB16: --- | AC16: --- | AD16: --- | AE16: =AE43*AE70*AE97*$AY16 -> 50 | AF16: --- | AG16: --- | AH16: --- | AI16: --- | AJ16: --- | AL16: 16 | AM16: --- | AN16: --- | AO16: --- | AP16: --- | AQ16: 0 | AR16: --- | AS16: --- | AT16: --- | AU16: --- | AV16: --- | AX16: 0.75 | AY16: 0.5 | AZ16: 0.5
B17: 31 | D17: --- | E17: --- | F17: --- | G17: --- | H17: --- | I17: 60000 | J17: 60000 | K17: 60000 | L17: 80000 | M17: --- | N17: 250 | O17: --- | P17: --- | Q17: --- | R17: --- | S17: --- | T17: =I17/$N17 -> 240 | U17: =J17/$N17 -> 240 | V17: =K17/$N17 -> 240 | W17: =L17/$N17 -> 320 | X17: --- | Z17: 31 | AA17: --- | AB17: --- | AC17: --- | AD17: --- | AE17: --- | AF17: =AF44*AF71*AF98*$AY17 -> 675 | AG17: =AG44*AG71*AG98*$AY17 -> 675 | AH17: =AH44*AH71*AH98*$AY17 -> 675 | AI17: =AI44*AI71*AI98*$AY17 -> 225 | AJ17: --- | AL17: 31 | AM17: --- | AN17: --- | AO17: --- | AP17: --- | AQ17: --- | AR17: 0.3 | AS17: 0.3 | AT17: 0.3 | AU17: 0.3 | AV17: --- | AX17: 0.9 | AY17: 0.9 | AZ17: 0.5
B18: 32 | D18: --- | E18: --- | F18: --- | G18: --- | H18: --- | I18: --- | J18: --- | K18: --- | L18: 80000 | M18: 100000 | N18: 250 | O18: --- | P18: --- | Q18: --- | R18: --- | S18: --- | T18: --- | U18: --- | V18: --- | W18: =L18/$N18 -> 320 | X18: =M18/$N18 -> 400 | Z18: 32 | AA18: --- | AB18: --- | AC18: --- | AD18: --- | AE18: --- | AF18: --- | AG18: --- | AH18: --- | AI18: =AI45*AI72*AI99*$AY18 -> 125 | AJ18: =AJ45*AJ72*AJ99*$AY18 -> 225 | AL18: 32 | AM18: --- | AN18: --- | AO18: --- | AP18: --- | AQ18: --- | AR18: --- | AS18: --- | AT18: --- | AU18: 0.3 | AV18: 0.3 | AX18: 0.9 | AY18: 0.5 | AZ18: 0.5
B19: 33 | D19: --- | E19: --- | F19: --- | G19: --- | H19: --- | I19: 60000 | J19: 60000 | K19: 60000 | L19: 80000 | M19: --- | N19: 250 | O19: --- | P19: --- | Q19: --- | R19: --- | S19: --- | T19: =I19/$N19 -> 240 | U19: =J19/$N19 -> 240 | V19: =K19/$N19 -> 240 | W19: =L19/$N19 -> 320 | X19: --- | Z19: 33 | AA19: --- | AB19: --- | AC19: --- | AD19: --- | AE19: --- | AF19: =AF46*AF73*AF100*$AY19 -> 675 | AG19: =AG46*AG73*AG100*$AY19 -> 675 | AH19: =AH46*AH73*AH100*$AY19 -> 675 | AI19: =AI46*AI73*AI100*$AY19 -> 225 | AJ19: --- | AL19: 33 | AM19: --- | AN19: --- | AO19: --- | AP19: --- | AQ19: --- | AR19: 0.3 | AS19: 0.3 | AT19: 0.3 | AU19: 0.3 | AV19: --- | AX19: 0.9 | AY19: 0.9 | AZ19: 0.5
B20: 34 | D20: --- | E20: --- | F20: --- | G20: --- | H20: --- | I20: --- | J20: --- | K20: --- | L20: 80000 | M20: 100000 | N20: 250 | O20: --- | P20: --- | Q20: --- | R20: --- | S20: --- | T20: --- | U20: --- | V20: --- | W20: =L20/$N20 -> 320 | X20: =M20/$N20 -> 400 | Z20: 34 | AA20: --- | AB20: --- | AC20: --- | AD20: --- | AE20: --- | AF20: --- | AG20: --- | AH20: --- | AI20: =AI47*AI74*AI101*$AY20 -> 125 | AJ20: =AJ47*AJ74*AJ101*$AY20 -> 225 | AL20: 34 | AM20: --- | AN20: --- | AO20: --- | AP20: --- | AQ20: --- | AR20: --- | AS20: --- | AT20: --- | AU20: 0.3 | AV20: 0.3 | AX20: 0.9 | AY20: 0.5 | AZ20: 0.5
B21: 35 | D21: --- | E21: --- | F21: --- | G21: --- | H21: --- | I21: 60000 | J21: 60000 | K21: 60000 | L21: 80000 | M21: --- | N21: 250 | O21: --- | P21: --- | Q21: --- | R21: --- | S21: --- | T21: =I21/$N21 -> 240 | U21: =J21/$N21 -> 240 | V21: =K21/$N21 -> 240 | W21: =L21/$N21 -> 320 | X21: --- | Z21: 35 | AA21: --- | AB21: --- | AC21: --- | AD21: --- | AE21: --- | AF21: =AF48*AF75*AF102*$AY21 -> 675 | AG21: =AG48*AG75*AG102*$AY21 -> 675 | AH21: =AH48*AH75*AH102*$AY21 -> 675 | AI21: =AI48*AI75*AI102*$AY21 -> 225 | AJ21: --- | AL21: 35 | AM21: --- | AN21: --- | AO21: --- | AP21: --- | AQ21: --- | AR21: 0.3 | AS21: 0.3 | AT21: 0.3 | AU21: 0.3 | AV21: --- | AX21: 0.9 | AY21: 0.9 | AZ21: 0.5
B22: 36 | D22: --- | E22: --- | F22: --- | G22: --- | H22: --- | I22: --- | J22: --- | K22: --- | L22: 80000 | M22: 100000 | N22: 250 | O22: --- | P22: --- | Q22: --- | R22: --- | S22: --- | T22: --- | U22: --- | V22: --- | W22: =L22/$N22 -> 320 | X22: =M22/$N22 -> 400 | Z22: 36 | AA22: --- | AB22: --- | AC22: --- | AD22: --- | AE22: --- | AF22: --- | AG22: --- | AH22: --- | AI22: =AI49*AI76*AI103*$AY22 -> 125 | AJ22: =AJ49*AJ76*AJ103*$AY22 -> 225 | AL22: 36 | AM22: --- | AN22: --- | AO22: --- | AP22: --- | AQ22: --- | AR22: --- | AS22: --- | AT22: --- | AU22: 0.3 | AV22: 0.3 | AX22: 0.9 | AY22: 0.5 | AZ22: 0.5
B23: 37 | D23: --- | E23: --- | F23: --- | G23: --- | H23: --- | I23: 60000 | J23: 60000 | K23: 60000 | L23: 80000 | M23: --- | N23: 250 | O23: --- | P23: --- | Q23: --- | R23: --- | S23: --- | T23: =I23/$N23 -> 240 | U23: =J23/$N23 -> 240 | V23: =K23/$N23 -> 240 | W23: =L23/$N23 -> 320 | X23: --- | Z23: 37 | AA23: --- | AB23: --- | AC23: --- | AD23: --- | AE23: --- | AF23: =AF50*AF77*AF104*$AY23 -> 675 | AG23: =AG50*AG77*AG104*$AY23 -> 675 | AH23: =AH50*AH77*AH104*$AY23 -> 675 | AI23: =AI50*AI77*AI104*$AY23 -> 225 | AJ23: --- | AL23: 37 | AM23: --- | AN23: --- | AO23: --- | AP23: --- | AQ23: --- | AR23: 0.3 | AS23: 0.3 | AT23: 0.3 | AU23: 0.3 | AV23: --- | AX23: 0.9 | AY23: 0.9 | AZ23: 0.5
B24: 38 | D24: --- | E24: --- | F24: --- | G24: --- | H24: --- | I24: --- | J24: --- | K24: --- | L24: 80000 | M24: 100000 | N24: 250 | O24: --- | P24: --- | Q24: --- | R24: --- | S24: --- | T24: --- | U24: --- | V24: --- | W24: =L24/$N24 -> 320 | X24: =M24/$N24 -> 400 | Z24: 38 | AA24: --- | AB24: --- | AC24: --- | AD24: --- | AE24: --- | AF24: --- | AG24: --- | AH24: --- | AI24: =AI51*AI78*AI105*$AY24 -> 125 | AJ24: =AJ51*AJ78*AJ105*$AY24 -> 225 | AL24: 38 | AM24: --- | AN24: --- | AO24: --- | AP24: --- | AQ24: --- | AR24: --- | AS24: --- | AT24: --- | AU24: 0.3 | AV24: 0.3 | AX24: 0.9 | AY24: 0.5 | AZ24: 0.5
B25: 39 | D25: --- | E25: --- | F25: --- | G25: --- | H25: --- | I25: 60000 | J25: 60000 | K25: 60000 | L25: 80000 | M25: --- | N25: 250 | O25: --- | P25: --- | Q25: --- | R25: --- | S25: --- | T25: =I25/$N25 -> 240 | U25: =J25/$N25 -> 240 | V25: =K25/$N25 -> 240 | W25: =L25/$N25 -> 320 | X25: --- | Z25: 39 | AA25: --- | AB25: --- | AC25: --- | AD25: --- | AE25: --- | AF25: =AF52*AF79*AF106*$AY25 -> 675 | AG25: =AG52*AG79*AG106*$AY25 -> 675 | AH25: =AH52*AH79*AH106*$AY25 -> 675 | AI25: =AI52*AI79*AI106*$AY25 -> 225 | AJ25: --- | AL25: 39 | AM25: --- | AN25: --- | AO25: --- | AP25: --- | AQ25: --- | AR25: 0.3 | AS25: 0.3 | AT25: 0.3 | AU25: 0.3 | AV25: --- | AX25: 0.9 | AY25: 0.9 | AZ25: 0.5
B26: 40 | D26: --- | E26: --- | F26: --- | G26: --- | H26: --- | I26: --- | J26: --- | K26: --- | L26: 80000 | M26: 100000 | N26: 250 | O26: --- | P26: --- | Q26: --- | R26: --- | S26: --- | T26: --- | U26: --- | V26: --- | W26: =L26/$N26 -> 320 | X26: =M26/$N26 -> 400 | Z26: 40 | AA26: --- | AB26: --- | AC26: --- | AD26: --- | AE26: --- | AF26: --- | AG26: --- | AH26: --- | AI26: =AI53*AI80*AI107*$AY26 -> 125 | AJ26: =AJ53*AJ80*AJ107*$AY26 -> 225 | AL26: 40 | AM26: --- | AN26: --- | AO26: --- | AP26: --- | AQ26: --- | AR26: --- | AS26: --- | AT26: --- | AU26: 0.3 | AV26: 0.3 | AX26: 0.9 | AY26: 0.5 | AZ26: 0.5
Z29: Vehicle group | AA29: Stationary charging max power from infrastructure [kW] | AL29: Vehicle group | AM29: Share of distance of total mission where in-motion charging infrastructure is available TROLLEY
AA30: Long haul | AB30: Regional delivery | AC30: Urban delivery | AD30: Municipal delivery | AE30: Con-struction | AF30: Heavy Urban | AG30: Urban | AH30: Suburban | AI30: Interurban | AJ30: Coach | AM30: Long haul | AN30: Regional delivery | AO30: Urban delivery | AP30: Municipal delivery | AQ30: Con-struction | AR30: Heavy Urban | AS30: Urban | AT30: Suburban | AU30: Interurban | AV30: Coach
Z31: 53 | AA31: --- | AB31: 250 | AC31: 250 | AD31: --- | AE31: --- | AF31: --- | AG31: --- | AH31: --- | AI31: --- | AJ31: --- | AL31: 53 | AM31: --- | AN31: 0 | AO31: 0 | AP31: --- | AQ31: --- | AR31: --- | AS31: --- | AT31: --- | AU31: --- | AV31: ---
Z32: 54 | AA32: --- | AB32: 250 | AC32: 250 | AD32: --- | AE32: --- | AF32: --- | AG32: --- | AH32: --- | AI32: --- | AJ32: --- | AL32: 54 | AM32: --- | AN32: 0 | AO32: 0 | AP32: --- | AQ32: --- | AR32: --- | AS32: --- | AT32: --- | AU32: --- | AV32: ---
Z33: 1s | AA33: --- | AB33: 250 | AC33: 250 | AD33: --- | AE33: --- | AF33: --- | AG33: --- | AH33: --- | AI33: --- | AJ33: --- | AL33: 1s | AM33: --- | AN33: 0 | AO33: 0 | AP33: --- | AQ33: --- | AR33: --- | AS33: --- | AT33: --- | AU33: --- | AV33: ---
Z34: 1 | AA34: --- | AB34: 250 | AC34: 250 | AD34: --- | AE34: --- | AF34: --- | AG34: --- | AH34: --- | AI34: --- | AJ34: --- | AL34: 1 | AM34: --- | AN34: 0 | AO34: 0 | AP34: --- | AQ34: --- | AR34: --- | AS34: --- | AT34: --- | AU34: --- | AV34: ---
Z35: 2 | AA35: 500 | AB35: 250 | AC35: 250 | AD35: --- | AE35: --- | AF35: --- | AG35: --- | AH35: --- | AI35: --- | AJ35: --- | AL35: 2 | AM35: 0 | AN35: 0 | AO35: 0 | AP35: --- | AQ35: --- | AR35: --- | AS35: --- | AT35: --- | AU35: --- | AV35: ---
Z36: 3 | AA36: --- | AB36: 250 | AC36: 250 | AD36: --- | AE36: --- | AF36: --- | AG36: --- | AH36: --- | AI36: --- | AJ36: --- | AL36: 3 | AM36: --- | AN36: 0 | AO36: 0 | AP36: --- | AQ36: --- | AR36: --- | AS36: --- | AT36: --- | AU36: --- | AV36: ---
Z37: 4 | AA37: 500 | AB37: 250 | AC37: 250 | AD37: 150 | AE37: 100 | AF37: --- | AG37: --- | AH37: --- | AI37: --- | AJ37: --- | AL37: 4 | AM37: 0 | AN37: 0 | AO37: 0 | AP37: 0 | AQ37: 0 | AR37: --- | AS37: --- | AT37: --- | AU37: --- | AV37: ---
Z38: 5 | AA38: 500 | AB38: 250 | AC38: 250 | AD38: --- | AE38: 100 | AF38: --- | AG38: --- | AH38: --- | AI38: --- | AJ38: --- | AL38: 5 | AM38: 0 | AN38: 0 | AO38: 0 | AP38: --- | AQ38: 0 | AR38: --- | AS38: --- | AT38: --- | AU38: --- | AV38: ---
Z39: 9 | AA39: 500 | AB39: 250 | AC39: --- | AD39: 150 | AE39: 100 | AF39: --- | AG39: --- | AH39: --- | AI39: --- | AJ39: --- | AL39: 9 | AM39: 0 | AN39: 0 | AO39: --- | AP39: 0 | AQ39: 0 | AR39: --- | AS39: --- | AT39: --- | AU39: --- | AV39: ---
Z40: 10 | AA40: 500 | AB40: 250 | AC40: --- | AD40: --- | AE40: 100 | AF40: --- | AG40: --- | AH40: --- | AI40: --- | AJ40: --- | AL40: 10 | AM40: 0 | AN40: 0 | AO40: --- | AP40: --- | AQ40: 0 | AR40: --- | AS40: --- | AT40: --- | AU40: --- | AV40: ---
Z41: 11 | AA41: 500 | AB41: 250 | AC41: --- | AD41: 150 | AE41: 100 | AF41: --- | AG41: --- | AH41: --- | AI41: --- | AJ41: --- | AL41: 11 | AM41: 0 | AN41: 0 | AO41: --- | AP41: 0 | AQ41: 0 | AR41: --- | AS41: --- | AT41: --- | AU41: --- | AV41: ---
Z42: 12 | AA42: 500 | AB42: 250 | AC42: --- | AD42: --- | AE42: 100 | AF42: --- | AG42: --- | AH42: --- | AI42: --- | AJ42: --- | AL42: 12 | AM42: 0 | AN42: 0 | AO42: --- | AP42: --- | AQ42: 0 | AR42: --- | AS42: --- | AT42: --- | AU42: --- | AV42: ---
Z43: 16 | AA43: --- | AB43: --- | AC43: --- | AD43: --- | AE43: 100 | AF43: --- | AG43: --- | AH43: --- | AI43: --- | AJ43: --- | AL43: 16 | AM43: --- | AN43: --- | AO43: --- | AP43: --- | AQ43: 0 | AR43: --- | AS43: --- | AT43: --- | AU43: --- | AV43: ---
...

Sheet Usable_SOC
J3: generic deterioration
J4: 0.05
C6: new vehicle | D6: new vehicle | E6: new vehicle | F6: new vehicle | G6: new vehicle | H6: new vehicle | I6: new vehicle | J6: half of lifetime | K6: half of lifetime | L6: half of lifetime | M6: half of lifetime
C7: generic SOC min | D7: generic SOC max | E7: declared SOC min | F7: declared SOC max | G7: actual SOC min | H7: actual SOC max | I7: useable SOC range | J7: useable SOC range | K7: average of SOC range ("SOCCENTER") | L7: actual SOC min | M7: actual SOC max
B8: PEV | C8: 0.05 | D8: 0.95 | G8: =MAX(C8,E8) -> 0.05 | H8: =MIN(D8,F8) -> 0.95 | I8: =H8-G8 -> 0.9 | J8: =I8*(1-J$4) -> 0.855 | K8: =AVERAGE(G8:H8) -> 0.5 | L8: =K8-J8/2 -> 0.0725 | M8: =K8+J8/2 -> 0.9275
B9: OVC-HEV and OVC_FCHV | C9: 0.15 | D9: 0.85 | E9: 0.3 | F9: 0.8 | G9: =MAX(C9,E9) -> 0.3 | H9: =MIN(D9,F9) -> 0.8 | I9: =H9-G9 -> 0.5 | J9: =I9*(1-J$4) -> 0.475 | K9: =AVERAGE(G9:H9) -> 0.55 | L9: =K9-J9/2 -> 0.3125 | M9: =K9+J9/2 -> 0.7875
B10: NOVC-HEV and NOVC-FCHV | C10: 0.25 | D10: 0.75 | E10: 0.4 | F10: 0.6 | G10: =MAX(C10,E10) -> 0.4 | H10: =MIN(D10,F10) -> 0.6 | I10: =H10-G10 -> 0.2 | J10: =I10*(1-J$4) -> 0.19 | K10: =AVERAGE(G10:H10) -> 0.5 | L10: =K10-J10/2 -> 0.405 | M10: =K10+J10/2 -> 0.595
B13: Remarks:
B14: Declaration of useable SOC range assumed to refer to new vehicle, otherwise it cannot be combined with declared deterioration (what is the vision for the future?)

Sheet BatteryData OVC-HEV
B3: Battery charging efficiency weighted average | C3: [-] | D3: =D9/(D9+D10)*D12 + D10/(D9+D10)*D13 -> 0.98554548
B6: Charging power DEPOT | C6: [kW] | D6: =MAX(10,'Template_OVC-HEV'!D10/6) -> 13.333333
B7: Charging power STATIONARY DURING MISSION | C7: [kW] | D7: =MIN('Template_OVC-HEV'!D9,'Template_OVC-HEV'!D20) -> 150
B9: Charged energy DEPOT | C9: [kWh] | D9: ='Template_OVC-HEV'!D23*'Template_OVC-HEV'!D10 -> 60
B10: Charged energy STATIONARY DURING MISSION | C10: [kWh] | D10: ='Template_OVC-HEV'!D29 -> 36.255537
B12: Battery charging efficiency DEPOT | C12: [-] | D12: =D18 -> 0.99686394
B13: Battery charging efficiency STATIONARY DURING MISSION | C13: [-] | D13: =D22 -> 0.96681432
B16: Charging power Depot | C16: [kW] | D16: =D6 -> 13.333333
B17: Loss power charging Depot | C17: [kW] | D17: =D30 -> 0.041814079
B18: Charging efficiency Depot | C18: - | D18: =1-D17/D16 -> 0.99686394
B20: Charging power during Mission | C20: [kW] | D20: =D7 -> 150
B21: Loss power charging during Mission | C21: [kW] | D21: =D33 -> 4.9778517
B22: Charging efficiency during Mission | C22: - | D22: =1-D21/D20 -> 0.96681432
B25: Calculations for battery component
B26: U_i @ SOC_center | C26: [V] | D26: 650 | F26: result from VECTO - HERE AS INPUT REQUIRED!
B27: R_i @ SOC_center | C27: [Ohm] | D27: 0.1 | F27: result from VECTO - HERE AS INPUT REQUIRED!
B29: Current charging Depot | C29: [A] | D29: =(-D26+SQRT(D26*D26-4*D27*D16*-1*1000))/2/D27 -> 20.448491
B30: P_loss charging Depot | C30: [kW] | D30: =D29*D29*D27/1000 -> 0.041814079
B32: Current charging Mission | C32: [A] | D32: =(-D26+SQRT(D26*D26-4*D27*D20*-1*1000))/2/D27 -> 223.111
B33: P_loss charging Mission | C33: [kW] | D33: =D32*D32*D27/1000 -> 4.9778517

Sheet Template_OVC-HEV
B2: Example: group 5 full hybrid in long haul cycle (OVC HEV, but no IMC)
B4: Colour code
B5: from generic data | D5: 123
B6: from VECTO input / simulation (numerical value as input to this consideration) | D6: 123
B7: as to be calculated for OVC vehicles in post-processing (There is a formula to look at here!) | D7: 123
B9: Max stat. charging power | C9: [kW] | D9: 150 | F9: declared in vehicle input
B10: Useable battery capacity | C10: [kWh] | D10: 80 | F10: certified capacity cut by generic or declared upper/lower limits and generic deterioration factor
B11: Electric energy consumption CD mode (battery internal, SOC) | C11: [kWh/km] | D11: 1.037 | F11: result from VECTO refering to battery internal (SOC related) electric energy
B12: FC CD mode | C12: [l/100km] | D12: 3.85
B13: FC CS mode | C13: [l/100km] | D13: 27.35
B15: Actual charge depleting range (RCDA) | C15: [km] | D15: =D10/D11 -> 77.145612
B16: Equivalent all electric range (EAER) | C16: [km] | D16: =D15*((D13-D12)/D13) -> 66.285992
B17: Zero CO2 emissions range | C17: [km] | D17: =D16 -> 66.285992
B19: Daily specific mileage | C19: [km/d] | D19: =GenericData_VehicleOperation!$O$11 -> 480
B20: Stationary charging during mission max. power from infrastructure | C20: [kW] | D20: =GenericData_VehicleOperation!$AA$38 -> 500
B21: Stationary charging during mission - average duration per event | C21: [h] | D21: =GenericData_VehicleOperation!$AA$65 -> 0.5
B22: Stationary charging during mission - number of events | C22: [-] | D22: =GenericData_VehicleOperation!$AA$92 -> 1
B23: Real world factor usage start SOC (part of max useable) | C23: [-] | D23: =GenericData_VehicleOperation!$AX$11 -> 0.75
B24: Real world factor usage charge during mission | C24: [-] | D24: =GenericData_VehicleOperation!$AY$11 -> 0.5
B25: Charging efficiency battery (weighted average) | C25: [-] | D25: ='BatteryData OVC-HEV'!D3 -> 0.98554548
B27: Electric range for UF from start SOC (stat charging at depot) | C27: [km] | D27: =D15*D23 -> 57.859209
B28: Charging efficiency battery for stationary charging during mission | C28: [-] | D28: ='BatteryData OVC-HEV'!D13 -> 0.96681432
B29: Electric energy charged during mission from stat infrastructure | C29: [kWh] | D29: =MIN(MIN(D9,D20)*D21*D28,D10)*D22*D24 -> 36.255537 | F29: considers limitation in max charging power from vehicle, battery capacity and number of charging events; real world usage factor applied to downscale number of events (and not charging power)
B30: Electric range for UF from stat charging during mission | C30: [km] | D30: =D29/D11 -> 34.961945
B32: UF | C32: [-] | D32: =MIN(1,(D27+D30)/D19) -> 0.1933774 | F32: cannot be >1
B34: EC_el_final CD | C34: [kWh/km] | D34: =D11/D25 -> 1.0522092 | F34: reference = battery terminals, thus battery charging losses to be added
B36: Electric energy consumption weighted CD + CS | C36: [kWh/km] | D36: =D32*D34 -> 0.20347348
B37: Fuel consumption weighted CD + CS | C37: [l/100km] | D37: =D32*D12+(1-D32)*D13 -> 22.805631

Sheet BatteryData PEV
B3: Battery charging efficiency | C3: [-] | D3: =D10 -> 0.99608605
B6: Charging power DEPOT | C6: [kW] | D6: =MAX(10,'Template_OVC-HEV'!D20/6) -> 83.333333
B8: Charged energy DEPOT | C8: [kWh] | D8: ='Template_OVC-HEV'!D23*'Template_OVC-HEV'!D10 -> 60
B10: Battery charging efficiency DEPOT | C10: [-] | D10: =D15 -> 0.99608605
B13: Charging power Depot | C13: [kW] | D13: =D6 -> 83.333333
B14: Loss power charging Depot | C14: [kW] | D14: =D24 -> 0.32616286
B15: Charging efficiency Depot | C15: - | D15: =1-D14/D13 -> 0.99608605
B19: Calculations for battery component
B20: U_i @ SOC_center | C20: [V] | D20: 650 | F20: result from VECTO - HERE AS INPUT REQUIRED!
B21: R_i @ SOC_center | C21: [Ohm] | D21: 0.02 | F21: result from VECTO - HERE AS INPUT REQUIRED!
B23: Current charging Depot | C23: [A] | D23: =(-D20+SQRT(D20*D20-4*D21*D13*-1*1000))/2/D21 -> 127.70334
B24: P_loss charging Depot | C24: [kW] | D24: =D23*D23*D21/1000 -> 0.32616286

Sheet Template_PEV
B2: Example: group 5 PEV in long haul cycle (no IMC)
B4: Colour code
B5: from generic data | D5: 123
B6: from VECTO input / simulation (numerical value as input to this consideration) | D6: 123
B7: as to be calculated for OVC vehicles in post-processing (There is a formula to look at here!) | D7: 123
B9: Useable battery capacity | C9: [kWh] | D9: 600 | F9: certified capacity cut by generic or declared upper/lower limits and generic deterioration factor
B10: Electric energy consumption CD mode (battery internal, SOC) | C10: [kWh/km] | D10: 1.234 | F10: result from VECTO refering to battery internal (SOC related) electric energy
B12: Actual charge depleting range (RCDA) | C12: [km] | D12: =D9/D10 -> 486.22366
B13: Equivalent all electric range (EAER) | C13: [km] | D13: =D12 -> 486.22366
B14: Zero CO2 emissions range | C14: [km] | D14: =D13 -> 486.22366
B16: Charging efficiency battery | C16: [-] | D16: ='BatteryData PEV'!D3 -> 0.99608605
B17: EC_el_final CD | C17: [kWh/km] | D17: =D10/D16 -> 1.2388488 | F17: reference = battery terminals, thus battery charging losses to be added

Sheet BatteryData IMC_OVC-HEV
B2: Vehicle type is city bus? | C2: No
M3: Yes
B4: Battery charging efficiency weighted average | C4: [-] | D4: =D10/(D10+D11+D12)*D14 + D11/(D10+D11+D12)*D15 + D12/(D10+D11+D12)*D16 -> 0.9890742 | M4: No
B6: Charging power DEPOT | C6: [kW] | D6: =MAX(10,'Template IMC_OVC-HEV'!D10/6) -> 13.333333
B7: Charging power STATIONARY DURING MISSION | C7: [kW] | D7: =MIN('Template IMC_OVC-HEV'!D9,'Template IMC_OVC-HEV'!D20) -> 150
B8: Charging power IN-MOTION CHARGING SOC LIFT | C8: [kW] | D8: =IF(C2="No",100,30) -> 100
B10: Charged energy DEPOT | C10: [kWh] | D10: ='Template IMC_OVC-HEV'!D29 -> 60
B11: Charged energy STATIONARY DURING MISSION | C11: [kWh] | D11: ='Template IMC_OVC-HEV'!D31 -> 0
B12: Charged energy IN-MOTION CHARGING SOC LIFT | C12: [kWh] | D12: ='Template IMC_OVC-HEV'!D35 -> 40
B14: Battery charging efficiency DEPOT | C14: [-] | D14: =D21 -> 0.99686394
B15: Battery charging efficiency STATIONARY DURING MISSION | C15: [-] | D15: =D25 -> 0.96681432
B16: Battery charging efficiency IN-MOTION CHARGING SOC LIFT | C16: [-] | D16: =D29 -> 0.97738958
B19: Charging power Depot | C19: [kW] | D19: =D6 -> 13.333333
B20: Loss power charging Depot | C20: [kW] | D20: =D37 -> 0.041814079
B21: Charging efficiency Depot | C21: - | D21: =1-D20/D19 -> 0.99686394
B23: Charging power during Mission | C23: [kW] | D23: =D7 -> 150
B24: Loss power charging during Mission | C24: [kW] | D24: =D40 -> 4.9778517
B25: Charging efficiency during Mission | C25: - | D25: =1-D24/D23 -> 0.96681432
B27: Charging power during IMC SOC lift | C27: [kW] | D27: =D8 -> 100
B28: Loss power charging during IMC SOC lift | C28: [kW] | D28: =D43 -> 2.2610423
B29: Charging efficiency during IMC SOC lift | C29: - | D29: =1-D28/D27 -> 0.97738958
B32: Calculations for battery component
B33: U_i @ SOC_center | C33: [V] | D33: 650 | F33: result from VECTO - HERE AS INPUT REQUIRED!
B34: R_i @ SOC_center | C34: [Ohm] | D34: 0.1 | F34: result from VECTO - HERE AS INPUT REQUIRED!
B36: Current charging Depot | C36: [A] | D36: =(-$D$33+SQRT($D$33*$D$33-4*$D$34*D19*-1*1000))/2/$D$34 -> 20.448491
B37: P_loss charging Depot | C37: [kW] | D37: =D36*D36*$D$34/1000 -> 0.041814079
B39: Current charging Mission | C39: [A] | D39: =(-$D$33+SQRT($D$33*$D$33-4*$D$34*D23*-1*1000))/2/$D$34 -> 223.111
B40: P_loss charging Mission | C40: [kW] | D40: =D39*D39*$D$34/1000 -> 4.9778517
B42: Current charging IMC SOC lift | C42: [A] | D42: =(-$D$33+SQRT($D$33*$D$33-4*$D$34*D27*-1*1000))/2/$D$34 -> 150.36763
B43: P_loss charging IMC SOC lift | C43: [kW] | D43: =D42*D42*$D$34/1000 -> 2.2610423

Sheet Template IMC_OVC-HEV
B2: Example: group 5 full hybrid in long haul cycle with IMC
B4: Colour code
B5: from generic data | D5: 123
B6: from VECTO input / simulation (numerical value as input to this consideration) | D6: 123
B7: as to be calculated for OVC vehicles in post-processing (There is a formula to look at here!) | D7: 123
B9: Max stat. charging power | C9: [kW] | D9: 150 | F9: declared in vehicle input (not of relevance here as no charge during mission)
B10: Useable battery capacity | C10: [kWh] | D10: 80 | F10: certified capacity cut by generic or declared upper/lower limits and generic deterioration factor
B11: Electric energy consumption CD mode (battery internal, SOC) | C11: [kWh/km] | D11: 1.037 | F11: result from VECTO refering to battery internal (SOC related) electric energy
B12: FC CD mode | C12: [l/100km] | D12: 3.85
B13: FC CS mode | C13: [l/100km] | D13: 27.35
B15: Actual charge depleting range (RCDA) | C15: [km] | D15: =D10/D11 -> 77.145612
B16: Equivalent all electric range (EAER) | C16: [km] | D16: =D15*((D13-D12)/D13) -> 66.285992
B17: Zero CO2 emissions range | C17: [km] | D17: =D16 -> 66.285992
B19: Daily specific mileage | C19: [km/d] | D19: =GenericData_VehicleOperation!$O$11 -> 480 | F19: Depending on the vehicle group and IMC technology, the correct generic parameters need to be used for all generic parameters!
B20: Stationary charging during mission max. power from infrastructure | C20: [kW] | D20: =GenericData_VehicleOperation!$AA$38 -> 500
B21: Stationary charging during mission - average duration per event | C21: [h] | D21: =GenericData_VehicleOperation!$AA$65 -> 0.5
B22: Stationary charging during mission - number of events | C22: [-] | D22: =GenericData_VehicleOperation!$AA$92 -> 1
B23: Real world factor usage start SOC (part of max useable) | C23: [-] | D23: =GenericData_VehicleOperation!$AX$11 -> 0.75
B24: Real world factor usage charge during mission | C24: [-] | D24: 0
B25: Share of distance where in-motion charging infrastructure is available | C25: [-] | D25: =GenericData_VehicleOperation!$AM$11 -> 0.5
B26: Real world factor in-motion charging during mission (lift in % of useable SOC) | C26: [-] | D26: =GenericData_VehicleOperation!$AZ$11 -> 0.5
B28: Electric range for UF from start SOC (stat charging at depot) | C28: [km] | D28: =D15*D23 -> 57.859209
B29: Electric energy from start SOC (stat charging at depot) | C29: [kWh] | D29: =D28*D11 -> 60
B30: Charging efficiency battery for stationary charging during mission | C30: [-] | D30: ='BatteryData IMC_OVC-HEV'!D15 -> 0.96681432
B31: Electric energy charged during mission from stat infrastructure | C31: [kWh] | D31: =MIN(MIN(D9,D20)*D21*D30,D10)*D22*D24 -> 0 | F31: considers limitation in max charging power from vehicle, battery capacity and number of charging events; real world usage factor applied to downscale number of events (and not charging power)
B32: Electric range for UF from stat charging during mission | C32: [km] | D32: =D31/D11 -> 0
B33: Electric range for UF from in-motion charging (only direct feed) | C33: [km] | D33: =D19*D25 -> 240
B34: Electric energy direct feed | C34: [kWh] | D34: =D11*D33 -> 248.88
B35: Electric energy charged during mission from in-motion infrastructure (SOC lift) | C35: [kWh] | D35: =D10*D26 -> 40
B36: Electric range for UF from in-motion charging during mission (SOC lift) | C36: [km] | D36: =D35/D11 -> 38.572806
B38: UF | C38: [-] | D38: =MIN(1,(D28+D32+D33+D36)/D19) -> 0.70090003 | F38: cannot be >1
B40: Electric energy required for daily specific mileage | C40: [kWh] | D40: =D19*D11 -> 497.76
B41: Limitation of electric energy charged into the battery | C41: [kWh] | D41: =MAX(D40-D34,0) -> 248.88 | F41: Electric energy provided by direct feed is always used completely!
B43: Share electric energy from grid first charged into battery | C43: [-] | D43: =D41/D40 -> 0.5
B44: Average charging efficiency battery during external charging (η_bat(1)) | C44: [-] | D44: ='BatteryData IMC_OVC-HEV'!D4 -> 0.9890742
B45: Share electric energy from grid direct feed | C45: [-] | D45: =1-D43 -> 0.5
B46: Average discharging efficiency battery during mission (η_bat(2)) | C46: [-] | D46: 0.9721 | F46: result from VECTO, here required as input
B48: Correction factor EC_SOC as simulated by VECTO to EC_terminal | C48: [-] | D48: =D43*(1/D44) + D45*D46 -> 0.99157325
B50: EC_el_final CD | C50: [kWh/km] | D50: =D11*D48 -> 1.0282615 | F50: reference = battery terminals, thus battery charging losses to be added
B52: Electric energy consumption weighted CD + CS | C52: [kWh/km] | D52: =D38*D50 -> 0.72070849
...

Sheet BatteryData IMC_PEV
B2: Vehicle type is city bus? | C2: No
M3: Yes
B4: Battery charging efficiency | C4: [-] | D4: =D10/(D10+D11)*D13 + D11/(D10+D11)*D14 -> 0.99577585 | M4: No
B7: Charging power DEPOT | C7: [kW] | D7: =MAX(10,'Template_OVC-HEV'!D20/6) -> 83.333333
B8: Charging power IN-MOTION CHARGING SOC LIFT | C8: [kW] | D8: =IF(C2="No",100,30) -> 100
B10: Charged energy DEPOT | C10: [kWh] | D10: ='Template IMC_PEV'!D21 -> 450
B11: Charged energy IN-MOTION CHARGING SOC LIFT | C11: [kWh] | D11: ='Template IMC_PEV'!D23 -> 300
B13: Battery charging efficiency DEPOT | C13: [-] | D13: =D19 -> 0.99608605
B14: Battery charging efficiency IN-MOTION CHARGING SOC LIFT | C14: [-] | D14: =D23 -> 0.99531057
B17: Charging power Depot | C17: [kW] | D17: =D7 -> 83.333333
B18: Loss power charging Depot | C18: [kW] | D18: =D31 -> 0.32616286
B19: Charging efficiency Depot | C19: - | D19: =1-D18/D17 -> 0.99608605
B21: Charging power during IMC SOC lift | C21: [kW] | D21: =D8 -> 100
B22: Loss power charging during IMC SOC lift | C22: [kW] | D22: =D34 -> 0.46894349
B23: Charging efficiency during IMC SOC lift | C23: - | D23: =1-D22/D21 -> 0.99531057
B26: Calculations for battery component
B27: U_i @ SOC_center | C27: [V] | D27: 650 | F27: result from VECTO - HERE AS INPUT REQUIRED!
B28: R_i @ SOC_center | C28: [Ohm] | D28: 0.02 | F28: result from VECTO - HERE AS INPUT REQUIRED!
B30: Current charging Depot | C30: [A] | D30: =(-$D$27+SQRT($D$27*$D$27-4*$D$28*D17*-1*1000))/2/$D$28 -> 127.70334
B31: P_loss charging Depot | C31: [kW] | D31: =D30*D30*$D$28/1000 -> 0.32616286
B33: Current charging IMC SOC lift | C33: [A] | D33: =(-$D$27+SQRT($D$27*$D$27-4*$D$28*D21*-1*1000))/2/$D$28 -> 153.1247
B34: P_loss charging IMC SOC lift | C34: [kW] | D34: =D33*D33*$D$28/1000 -> 0.46894349

Sheet Template IMC_PEV
B2: Example: group 5 PEV in long haul cycle with IMC
B4: Colour code
B5: from generic data | D5: 123
B6: from VECTO input / simulation (numerical value as input to this consideration) | D6: 123
B7: as to be calculated for OVC vehicles in post-processing (There is a formula to look at here!) | D7: 123
B9: Useable battery capacity | C9: [kWh] | D9: 600 | F9: certified capacity cut by generic or declared upper/lower limits and generic deterioration factor
B10: Electric energy consumption CD mode (battery internal, SOC) | C10: [kWh/km] | D10: 1.234 | F10: result from VECTO refering to battery internal (SOC related) electric energy
B12: Actual charge depleting range (RCDA) | C12: [km] | D12: =D9/D10 -> 486.22366
B13: Equivalent all electric range (EAER) | C13: [km] | D13: =D12 -> 486.22366
B14: Zero CO2 emissions range | C14: [km] | D14: =D13 -> 486.22366
B16: Daily specific mileage | C16: [km/d] | D16: =GenericData_VehicleOperation!$O$11 -> 480 | F16: Depending on the vehicle group and IMC technology, the correct generic parameters need to be used for all generic parameters!
B17: Real world factor usage start SOC (part of max useable) | C17: [-] | D17: =GenericData_VehicleOperation!$AX$11 -> 0.75
B18: Share of distance where in-motion charging infrastructure is available | C18: [-] | D18: =GenericData_VehicleOperation!$AM$11 -> 0.5
B19: Real world factor in-motion charging during mission (lift in % of useable SOC) | C19: [-] | D19: =GenericData_VehicleOperation!$AZ$11 -> 0.5
B21: Electric energy from start SOC (stat charging at depot) | C21: [kWh] | D21: =D17*D9 -> 450
B22: Electric energy direct feed | C22: [kWh] | D22: =D18*D16*D10 -> 296.16
B23: Electric energy charged during mission from in-motion infrastructure (SOC lift) | C23: [kWh] | D23: =D19*D9 -> 300
B25: Electric energy required for daily specific mileage | C25: [kWh] | D25: =D10*D16 -> 592.32
B26: Limitation of electric energy charged into the battery | C26: [kWh] | D26: =MAX(D25-D22,0) -> 296.16 | F26: Electric energy provided by direct feed is always used completely!
B28: Share electric energy from grid first charged into battery | C28: [-] | D28: =D26/D25 -> 0.5
B29: Average charging efficiency battery during external charging (η_bat(1)) | C29: [-] | D29: ='BatteryData IMC_PEV'!D4 -> 0.99577585
B30: Share electric energy from grid direct feed | C30: [-] | D30: =1-D28 -> 0.5
B31: Average discharging efficiency battery during mission (η_bat(2)) | C31: [-] | D31: 0.9721 | F31: result from VECTO, here required as input
B33: Correction factor EC_SOC as simulated by VECTO to EC_terminal | C33: [-] | D33: =D28*(1/D29) + D30*D31 -> 0.98817103
B35: EC_el_final CD | C35: [kWh/km] | D35: =D10*D33 -> 1.2194031 | F35: reference = battery terminals, thus battery charging losses to be added
